Workbook
Name Slicer_Department: #N/A
Name Slicer_Status: #N/A

Sheet Cleaned Data
A1: CLEANED ATTENDANCE DATA
A2: Emp ID | B2: Employee Name | C2: Department | D2: Date | E2: Status | F2: Login Time | G2: Logout Time | H2: Calc. Hours | I2: Login Status | J2: Attendance Category | K2: Hours Check | L2: Category Match | M2: Data Quality
A3: EMP004 | B3: Sneha Reddy | C3: Sales | D3: 2026-01-01 | E3: Present | F3: 08:05 | G3: 20:45 | H3: =IFERROR(MOD(TIMEVALUE(G3)-TIMEVALUE(F3),1)*24,0) -> 12.666667 | I3: =IF(F3="No Login","",IF(TIMEVALUE(F3)>TIMEVALUE("09:00"),"Late","On Time")) -> On Time | J3: =IF(E3="Absent","Absent",IF(H3>=8,"Full Day",IF(H3>=4,"Half Day","Short"))) -> Full Day | K3: =IF(E3="Absent","N/A",IF(H3>=8,"Full Day",IF(H3>=4,"Half Day","Short"))) -> Full Day | L3: =IF(J3=K3,"✓ Match","⚠ Mismatch") -> ✓ Match | M3: =IF(AND(J3=K3,OR(E3="Present",E3="Work From Home",E3="Absent")),"CLEAN","REVIEW") -> CLEAN
A4: EMP005 | B4: Vijay | C4: IT | D4: 2026-01-01 | E4: Absent | F4: No Login | G4: No Logout | H4: 0 | I4: =IF(F4="No Login","",IF(TIMEVALUE(F4)>TIMEVALUE("09:00"),"Late","On Time")) | J4: =IF(E4="Absent","Absent",IF(H4>=8,"Full Day",IF(H4>=4,"Half Day","Short"))) -> Absent | K4: =IF(E4="Absent","N/A",IF(H4>=8,"Full Day",IF(H4>=4,"Half Day","Short"))) -> N/A | L4: =IF(J4=K4,"✓ Match","⚠ Mismatch") -> ⚠ Mismatch | M4: =IF(AND(J4=K4,OR(E4="Present",E4="Work From Home",E4="Absent")),"CLEAN","REVIEW") -> REVIEW
A5: EMP021 | B5: Nitin Sharma | C5: Sales | D5: 2026-01-01 | E5: Absent | F5: No Login | G5: No Logout | H5: 0 | I5: =IF(F5="No Login","",IF(TIMEVALUE(F5)>TIMEVALUE("09:00"),"Late","On Time")) | J5: =IF(E5="Absent","Absent",IF(H5>=8,"Full Day",IF(H5>=4,"Half Day","Short"))) -> Absent | K5: =IF(E5="Absent","N/A",IF(H5>=8,"Full Day",IF(H5>=4,"Half Day","Short"))) -> N/A | L5: =IF(J5=K5,"✓ Match","⚠ Mismatch") -> ⚠ Mismatch | M5: =IF(AND(J5=K5,OR(E5="Present",E5="Work From Home",E5="Absent")),"CLEAN","REVIEW") -> REVIEW
A6: EMP023 | B6: Harish Kumar | C6: HR | D6: 2026-01-01 | E6: Present | F6: 08:20 | G6: 20:15 | H6: =IFERROR(MOD(TIMEVALUE(G6)-TIMEVALUE(F6),1)*24,0) -> 11.916667 | I6: =IF(F6="No Login","",IF(TIMEVALUE(F6)>TIMEVALUE("09:00"),"Late","On Time")) -> On Time | J6: =IF(E6="Absent","Absent",IF(H6>=8,"Full Day",IF(H6>=4,"Half Day","Short"))) -> Full Day | K6: =IF(E6="Absent","N/A",IF(H6>=8,"Full Day",IF(H6>=4,"Half Day","Short"))) -> Full Day | L6: =IF(J6=K6,"✓ Match","⚠ Mismatch") -> ✓ Match | M6: =IF(AND(J6=K6,OR(E6="Present",E6="Work From Home",E6="Absent")),"CLEAN","REVIEW") -> CLEAN
A7: EMP008 | B7: Divya | C7: IT | D7: 2026-01-01 | E7: Present | F7: 08:45 | G7: 17:00 | H7: =IFERROR(MOD(TIMEVALUE(G7)-TIMEVALUE(F7),1)*24,0) -> 8.25 | I7: =IF(F7="No Login","",IF(TIMEVALUE(F7)>TIMEVALUE("09:00"),"Late","On Time")) -> On Time | J7: =IF(E7="Absent","Absent",IF(H7>=8,"Full Day",IF(H7>=4,"Half Day","Short"))) -> Full Day | K7: =IF(E7="Absent","N/A",IF(H7>=8,"Full Day",IF(H7>=4,"Half Day","Short"))) -> Full Day | L7: =IF(J7=K7,"✓ Match","⚠ Mismatch") -> ✓ Match | M7: =IF(AND(J7=K7,OR(E7="Present",E7="Work From Home",E7="Absent")),"CLEAN","REVIEW") -> CLEAN
A8: EMP024 | B8: Maheswari | C8: Finance | D8: 2026-01-01 | E8: Present | F8: 09:30 | G8: 19:10 | H8: =IFERROR(MOD(TIMEVALUE(G8)-TIMEVALUE(F8),1)*24,0) -> 9.6666667 | I8: =IF(F8="No Login","",IF(TIMEVALUE(F8)>TIMEVALUE("09:00"),"Late","On Time")) -> Late | J8: =IF(E8="Absent","Absent",IF(H8>=8,"Full Day",IF(H8>=4,"Half Day","Short"))) -> Full Day | K8: =IF(E8="Absent","N/A",IF(H8>=8,"Full Day",IF(H8>=4,"Half Day","Short"))) -> Full Day | L8: =IF(J8=K8,"✓ Match","⚠ Mismatch") -> ✓ Match | M8: =IF(AND(J8=K8,OR(E8="Present",E8="Work From Home",E8="Absent")),"CLEAN","REVIEW") -> CLEAN
A9: EMP027 | B9: Ashok Kumar | C9: Sales | D9: 2026-01-01 | E9: Present | F9: 09:10 | G9: 17:10 | H9: =IFERROR(MOD(TIMEVALUE(G9)-TIMEVALUE(F9),1)*24,0) -> 8 | I9: =IF(F9="No Login","",IF(TIMEVALUE(F9)>TIMEVALUE("09:00"),"Late","On Time")) -> Late | J9: =IF(E9="Absent","Absent",IF(H9>=8,"Full Day",IF(H9>=4,"Half Day","Short"))) -> Full Day | K9: =IF(E9="Absent","N/A",IF(H9>=8,"Full Day",IF(H9>=4,"Half Day","Short"))) -> Full Day | L9: =IF(J9=K9,"✓ Match","⚠ Mismatch") -> ✓ Match | M9: =IF(AND(J9=K9,OR(E9="Present",E9="Work From Home",E9="Absent")),"CLEAN","REVIEW") -> CLEAN
A10: EMP019 | B10: Rohit Malhotra | C10: Operations | D10: 2026-01-01 | E10: Present | F10: 09:10 | G10: 20:45 | H10: =IFERROR(MOD(TIMEVALUE(G10)-TIMEVALUE(F10),1)*24,0) -> 11.583333 | I10: =IF(F10="No Login","",IF(TIMEVALUE(F10)>TIMEVALUE("09:00"),"Late","On Time")) -> Late | J10: =IF(E10="Absent","Absent",IF(H10>=8,"Full Day",IF(H10>=4,"Half Day","Short"))) -> Full Day | K10: =IF(E10="Absent","N/A",IF(H10>=8,"Full Day",IF(H10>=4,"Half Day","Short"))) -> Full Day | L10: =IF(J10=K10,"✓ Match","⚠ Mismatch") -> ✓ Match | M10: =IF(AND(J10=K10,OR(E10="Present",E10="Work From Home",E10="Absent")),"CLEAN","REVIEW") -> CLEAN
A11: EMP006 | B11: Anjali | C11: IT | D11: 2026-01-01 | E11: Present | F11: 09:10 | G11: 16:10 | H11: =IFERROR(MOD(TIMEVALUE(G11)-TIMEVALUE(F11),1)*24,0) -> 7 | I11: =IF(F11="No Login","",IF(TIMEVALUE(F11)>TIMEVALUE("09:00"),"Late","On Time")) -> Late | J11: =IF(E11="Absent","Absent",IF(H11>=8,"Full Day",IF(H11>=4,"Half Day","Short"))) -> Half Day | K11: =IF(E11="Absent","N/A",IF(H11>=8,"Full Day",IF(H11>=4,"Half Day","Short"))) -> Half Day | L11: =IF(J11=K11,"✓ Match","⚠ Mismatch") -> ✓ Match | M11: =IF(AND(J11=K11,OR(E11="Present",E11="Work From Home",E11="Absent")),"CLEAN","REVIEW") -> CLEAN
A12: EMP017 | B12: Deepak | C12: HR | D12: 2026-01-01 | E12: Present | F12: 08:10 | G12: 20:45 | H12: =IFERROR(MOD(TIMEVALUE(G12)-TIMEVALUE(F12),1)*24,0) -> 12.583333 | I12: =IF(F12="No Login","",IF(TIMEVALUE(F12)>TIMEVALUE("09:00"),"Late","On Time")) -> On Time | J12: =IF(E12="Absent","Absent",IF(H12>=8,"Full Day",IF(H12>=4,"Half Day","Short"))) -> Full Day | K12: =IF(E12="Absent","N/A",IF(H12>=8,"Full Day",IF(H12>=4,"Half Day","Short"))) -> Full Day | L12: =IF(J12=K12,"✓ Match","⚠ Mismatch") -> ✓ Match | M12: =IF(AND(J12=K12,OR(E12="Present",E12="Work From Home",E12="Absent")),"CLEAN","REVIEW") -> CLEAN
A13: EMP001 | B13: Arun Kumar | C13: HR | D13: 2026-01-01 | E13: Present | F13: 08:10 | G13: 16:10 | H13: =IFERROR(MOD(TIMEVALUE(G13)-TIMEVALUE(F13),1)*24,0) -> 8 | I13: =IF(F13="No Login","",IF(TIMEVALUE(F13)>TIMEVALUE("09:00"),"Late","On Time")) -> On Time | J13: =IF(E13="Absent","Absent",IF(H13>=8,"Full Day",IF(H13>=4,"Half Day","Short"))) -> Full Day | K13: =IF(E13="Absent","N/A",IF(H13>=8,"Full Day",IF(H13>=4,"Half Day","Short"))) -> Full Day | L13: =IF(J13=K13,"✓ Match","⚠ Mismatch") -> ✓ Match | M13: =IF(AND(J13=K13,OR(E13="Present",E13="Work From Home",E13="Absent")),"CLEAN","REVIEW") -> CLEAN
A14: EMP011 | B14: Ajay Rao | C14: Finance | D14: 2026-01-01 | E14: Work From Home | F14: 09:20 | G14: 18:45 | H14: =IFERROR(MOD(TIMEVALUE(G14)-TIMEVALUE(F14),1)*24,0) -> 9.4166667 | I14: =IF(F14="No Login","",IF(TIMEVALUE(F14)>TIMEVALUE("09:00"),"Late","On Time")) -> Late | J14: =IF(E14="Absent","Absent",IF(H14>=8,"Full Day",IF(H14>=4,"Half Day","Short"))) -> Full Day | K14: =IF(E14="Absent","N/A",IF(H14>=8,"Full Day",IF(H14>=4,"Half Day","Short"))) -> Full Day | L14: =IF(J14=K14,"✓ Match","⚠ Mismatch") -> ✓ Match | M14: =IF(AND(J14=K14,OR(E14="Present",E14="Work From Home",E14="Absent")),"CLEAN","REVIEW") -> CLEAN
A15: EMP020 | B15: Lakshmi Devi | C15: Sales | D15: 2026-01-01 | E15: Present | F15: 09:45 | G15: 16:10 | H15: =IFERROR(MOD(TIMEVALUE(G15)-TIMEVALUE(F15),1)*24,0) -> 6.4166667 | I15: =IF(F15="No Login","",IF(TIMEVALUE(F15)>TIMEVALUE("09:00"),"Late","On Time")) -> Late | J15: =IF(E15="Absent","Absent",IF(H15>=8,"Full Day",IF(H15>=4,"Half Day","Short"))) -> Half Day | K15: =IF(E15="Absent","N/A",IF(H15>=8,"Full Day",IF(H15>=4,"Half Day","Short"))) -> Half Day | L15: =IF(J15=K15,"✓ Match","⚠ Mismatch") -> ✓ Match | M15: =IF(AND(J15=K15,OR(E15="Present",E15="Work From Home",E15="Absent")),"CLEAN","REVIEW") -> CLEAN
A16: EMP029 | B16: Sanjana Roy | C16: IT | D16: 2026-01-01 | E16: Present | F16: 10:15 | G16: 20:00 | H16: =IFERROR(MOD(TIMEVALUE(G16)-TIMEVALUE(F16),1)*24,0) -> 9.75 | I16: =IF(F16="No Login","",IF(TIMEVALUE(F16)>TIMEVALUE("09:00"),"Late","On Time")) -> Late | J16: =IF(E16="Absent","Absent",IF(H16>=8,"Full Day",IF(H16>=4,"Half Day","Short"))) -> Full Day | K16: =IF(E16="Absent","N/A",IF(H16>=8,"Full Day",IF(H16>=4,"Half Day","Short"))) -> Full Day | L16: =IF(J16=K16,"✓ Match","⚠ Mismatch") -> ✓ Match | M16: =IF(AND(J16=K16,OR(E16="Present",E16="Work From Home",E16="Absent")),"CLEAN","REVIEW") -> CLEAN
A17: EMP030 | B17: Mohit Agarwal | C17: IT | D17: 2026-01-01 | E17: Present | F17: 09:15 | G17: 20:15 | H17: =IFERROR(MOD(TIMEVALUE(G17)-TIMEVALUE(F17),1)*24,0) -> 11 | I17: =IF(F17="No Login","",IF(TIMEVALUE(F17)>TIMEVALUE("09:00"),"Late","On Time")) -> Late | J17: =IF(E17="Absent","Absent",IF(H17>=8,"Full Day",IF(H17>=4,"Half Day","Short"))) -> Full Day | K17: =IF(E17="Absent","N/A",IF(H17>=8,"Full Day",IF(H17>=4,"Half Day","Short"))) -> Full Day | L17: =IF(J17=K17,"✓ Match","⚠ Mismatch") -> ✓ Match | M17: =IF(AND(J17=K17,OR(E17="Present",E17="Work From Home",E17="Absent")),"CLEAN","REVIEW") -> CLEAN
A18: EMP014 | B18: Neha | C18: Sales | D18: 2026-01-01 | E18: Absent | F18: No Login | G18: No Logout | H18: 0 | I18: =IF(F18="No Login","",IF(TIMEVALUE(F18)>TIMEVALUE("09:00"),"Late","On Time")) | J18: =IF(E18="Absent","Absent",IF(H18>=8,"Full Day",IF(H18>=4,"Half Day","Short"))) -> Absent | K18: =IF(E18="Absent","N/A",IF(H18>=8,"Full Day",IF(H18>=4,"Half Day","Short"))) -> N/A | L18: =IF(J18=K18,"✓ Match","⚠ Mismatch") -> ⚠ Mismatch | M18: =IF(AND(J18=K18,OR(E18="Present",E18="Work From Home",E18="Absent")),"CLEAN","REVIEW") -> REVIEW
A19: EMP022 | B19: Swathi Rao | C19: Operations | D19: 2026-01-01 | E19: Absent | F19: No Login | G19: No Logout | H19: 0 | I19: =IF(F19="No Login","",IF(TIMEVALUE(F19)>TIMEVALUE("09:00"),"Late","On Time")) | J19: =IF(E19="Absent","Absent",IF(H19>=8,"Full Day",IF(H19>=4,"Half Day","Short"))) -> Absent | K19: =IF(E19="Absent","N/A",IF(H19>=8,"Full Day",IF(H19>=4,"Half Day","Short"))) -> N/A | L19: =IF(J19=K19,"✓ Match","⚠ Mismatch") -> ⚠ Mismatch | M19: =IF(AND(J19=K19,OR(E19="Present",E19="Work From Home",E19="Absent")),"CLEAN","REVIEW") -> REVIEW
A20: EMP003 | B20: Rahul Verma | C20: HR | D20: 2026-01-01 | E20: Present | F20: 08:00 | G20: 16:10 | H20: =IFERROR(MOD(TIMEVALUE(G20)-TIMEVALUE(F20),1)*24,0) -> 8.1666667 | I20: =IF(F20="No Login","",IF(TIMEVALUE(F20)>TIMEVALUE("09:00"),"Late","On Time")) -> On Time | J20: =IF(E20="Absent","Absent",IF(H20>=8,"Full Day",IF(H20>=4,"Half Day","Short"))) -> Full Day | K20: =IF(E20="Absent","N/A",IF(H20>=8,"Full Day",IF(H20>=4,"Half Day","Short"))) -> Full Day | L20: =IF(J20=K20,"✓ Match","⚠ Mismatch") -> ✓ Match | M20: =IF(AND(J20=K20,OR(E20="Present",E20="Work From Home",E20="Absent")),"CLEAN","REVIEW") -> CLEAN
A21: EMP016 | B21: Kavya Menon | C21: IT | D21: 2026-01-01 | E21: Present | F21: 09:45 | G21: 18:10 | H21: =IFERROR(MOD(TIMEVALUE(G21)-TIMEVALUE(F21),1)*24,0) -> 8.4166667 | I21: =IF(F21="No Login","",IF(TIMEVALUE(F21)>TIMEVALUE("09:00"),"Late","On Time")) -> Late | J21: =IF(E21="Absent","Absent",IF(H21>=8,"Full Day",IF(H21>=4,"Half Day","Short"))) -> Full Day | K21: =IF(E21="Absent","N/A",IF(H21>=8,"Full Day",IF(H21>=4,"Half Day","Short"))) -> Full Day | L21: =IF(J21=K21,"✓ Match","⚠ Mismatch") -> ✓ Match | M21: =IF(AND(J21=K21,OR(E21="Present",E21="Work From Home",E21="Absent")),"CLEAN","REVIEW") -> CLEAN
A22: EMP026 | B22: Gayathri S | C22: IT | D22: 2026-01-01 | E22: Absent | F22: No Login | G22: No Logout | H22: 0 | I22: =IF(F22="No Login","",IF(TIMEVALUE(F22)>TIMEVALUE("09:00"),"Late","On Time")) | J22: =IF(E22="Absent","Absent",IF(H22>=8,"Full Day",IF(H22>=4,"Half Day","Short"))) -> Absent | K22: =IF(E22="Absent","N/A",IF(H22>=8,"Full Day",IF(H22>=4,"Half Day","Short"))) -> N/A | L22: =IF(J22=K22,"✓ Match","⚠ Mismatch") -> ⚠ Mismatch | M22: =IF(AND(J22=K22,OR(E22="Present",E22="Work From Home",E22="Absent")),"CLEAN","REVIEW") -> REVIEW
A23: EMP002 | B23: Priya Sharma | C23: Sales | D23: 2026-01-01 | E23: Present | F23: 08:30 | G23: 19:00 | H23: =IFERROR(MOD(TIMEVALUE(G23)-TIMEVALUE(F23),1)*24,0) -> 10.5 | I23: =IF(F23="No Login","",IF(TIMEVALUE(F23)>TIMEVALUE("09:00"),"Late","On Time")) -> On Time | J23: =IF(E23="Absent","Absent",IF(H23>=8,"Full Day",IF(H23>=4,"Half Day","Short"))) -> Full Day | K23: =IF(E23="Absent","N/A",IF(H23>=8,"Full Day",IF(H23>=4,"Half Day","Short"))) -> Full Day | L23: =IF(J23=K23,"✓ Match","⚠ Mismatch") -> ✓ Match | M23: =IF(AND(J23=K23,OR(E23="Present",E23="Work From Home",E23="Absent")),"CLEAN","REVIEW") -> CLEAN
A24: EMP010 | B24: Meena | C24: Finance | D24: 2026-01-01 | E24: Present | F24: 08:15 | G24: 19:00 | H24: =IFERROR(MOD(TIMEVALUE(G24)-TIMEVALUE(F24),1)*24,0) -> 10.75 | I24: =IF(F24="No Login","",IF(TIMEVALUE(F24)>TIMEVALUE("09:00"),"Late","On Time")) -> On Time | J24: =IF(E24="Absent","Absent",IF(H24>=8,"Full Day",IF(H24>=4,"Half Day","Short"))) -> Full Day | K24: =IF(E24="Absent","N/A",IF(H24>=8,"Full Day",IF(H24>=4,"Half Day","Short"))) -> Full Day | L24: =IF(J24=K24,"✓ Match","⚠ Mismatch") -> ✓ Match | M24: =IF(AND(J24=K24,OR(E24="Present",E24="Work From Home",E24="Absent")),"CLEAN","REVIEW") -> CLEAN
A25: EMP025 | B25: Varun Sethi | C25: HR | D25: 2026-01-01 | E25: Present | F25: 08:20 | G25: 19:15 | H25: =IFERROR(MOD(TIMEVALUE(G25)-TIMEVALUE(F25),1)*24,0) -> 10.916667 | I25: =IF(F25="No Login","",IF(TIMEVALUE(F25)>TIMEVALUE("09:00"),"Late","On Time")) -> On Time | J25: =IF(E25="Absent","Absent",IF(H25>=8,"Full Day",IF(H25>=4,"Half Day","Short"))) -> Full Day | K25: =IF(E25="Absent","N/A",IF(H25>=8,"Full Day",IF(H25>=4,"Half Day","Short"))) -> Full Day | L25: =IF(J25=K25,"✓ Match","⚠ Mismatch") -> ✓ Match | M25: =IF(AND(J25=K25,OR(E25="Present",E25="Work From Home",E25="Absent")),"CLEAN","REVIEW") -> CLEAN
A26: EMP007 | B26: Karan Patel | C26: Finance | D26: 2026-01-01 | E26: Absent | F26: No Login | G26: No Logout | H26: 0 | I26: =IF(F26="No Login","",IF(TIMEVALUE(F26)>TIMEVALUE("09:00"),"Late","On Time")) | J26: =IF(E26="Absent","Absent",IF(H26>=8,"Full Day",IF(H26>=4,"Half Day","Short"))) -> Absent | K26: =IF(E26="Absent","N/A",IF(H26>=8,"Full Day",IF(H26>=4,"Half Day","Short"))) -> N/A | L26: =IF(J26=K26,"✓ Match","⚠ Mismatch") -> ⚠ Mismatch | M26: =IF(AND(J26=K26,OR(E26="Present",E26="Work From Home",E26="Absent")),"CLEAN","REVIEW") -> REVIEW
A27: EMP009 | B27: Suresh Babu | C27: HR | D27: 2026-01-01 | E27: Present | F27: 08:45 | G27: 17:30 | H27: =IFERROR(MOD(TIMEVALUE(G27)-TIMEVALUE(F27),1)*24,0) -> 8.75 | I27: =IF(F27="No Login","",IF(TIMEVALUE(F27)>TIMEVALUE("09:00"),"Late","On Time")) -> On Time | J27: =IF(E27="Absent","Absent",IF(H27>=8,"Full Day",IF(H27>=4,"Half Day","Short"))) -> Full Day | K27: =IF(E27="Absent","N/A",IF(H27>=8,"Full Day",IF(H27>=4,"Half Day","Short"))) -> Full Day | L27: =IF(J27=K27,"✓ Match","⚠ Mismatch") -> ✓ Match | M27: =IF(AND(J27=K27,OR(E27="Present",E27="Work From Home",E27="Absent")),"CLEAN","REVIEW") -> CLEAN
A28: EMP012 | B28: Pooja Das | C28: Sales | D28: 2026-01-01 | E28: Present | F28: 10:20 | G28: 18:45 | H28: =IFERROR(MOD(TIMEVALUE(G28)-TIMEVALUE(F28),1)*24,0) -> 8.4166667 | I28: =IF(F28="No Login","",IF(TIMEVALUE(F28)>TIMEVALUE("09:00"),"Late","On Time")) -> Late | J28: =IF(E28="Absent","Absent",IF(H28>=8,"Full Day",IF(H28>=4,"Half Day","Short"))) -> Full Day | K28: =IF(E28="Absent","N/A",IF(H28>=8,"Full Day",IF(H28>=4,"Half Day","Short"))) -> Full Day | L28: =IF(J28=K28,"✓ Match","⚠ Mismatch") -> ✓ Match | M28: =IF(AND(J28=K28,OR(E28="Present",E28="Work From Home",E28="Absent")),"CLEAN","REVIEW") -> CLEAN
A29: EMP015 | B29: Manoj | C29: Finance | D29: 2026-01-01 | E29: Absent | F29: No Login | G29: No Logout | H29: 0 | I29: =IF(F29="No Login","",IF(TIMEVALUE(F29)>TIMEVALUE("09:00"),"Late","On Time")) | J29: =IF(E29="Absent","Absent",IF(H29>=8,"Full Day",IF(H29>=4,"Half Day","Short"))) -> Absent | K29: =IF(E29="Absent","N/A",IF(H29>=8,"Full Day",IF(H29>=4,"Half Day","Short"))) -> N/A | L29: =IF(J29=K29,"✓ Match","⚠ Mismatch") -> ⚠ Mismatch | M29: =IF(AND(J29=K29,OR(E29="Present",E29="Work From Home",E29="Absent")),"CLEAN","REVIEW") -> REVIEW
A30: EMP018 | B30: Aisha Khan | C30: Sales | D30: 2026-01-01 | E30: Present | F30: 09:05 | G30: 20:45 | H30: =IFERROR(MOD(TIMEVALUE(G30)-TIMEVALUE(F30),1)*24,0) -> 11.666667 | I30: =IF(F30="No Login","",IF(TIMEVALUE(F30)>TIMEVALUE("09:00"),"Late","On Time")) -> Late | J30: =IF(E30="Absent","Absent",IF(H30>=8,"Full Day",IF(H30>=4,"Half Day","Short"))) -> Full Day | K30: =IF(E30="Absent","N/A",IF(H30>=8,"Full Day",IF(H30>=4,"Half Day","Short"))) -> Full Day | L30: =IF(J30=K30,"✓ Match","⚠ Mismatch") -> ✓ Match | M30: =IF(AND(J30=K30,OR(E30="Present",E30="Work From Home",E30="Absent")),"CLEAN","REVIEW") -> CLEAN
A31: EMP013 | B31: Ramesh | C31: Sales | D31: 2026-01-01 | E31: Present | F31: 09:45 | G31: 18:00 | H31: =IFERROR(MOD(TIMEVALUE(G31)-TIMEVALUE(F31),1)*24,0) -> 8.25 | I31: =IF(F31="No Login","",IF(TIMEVALUE(F31)>TIMEVALUE("09:00"),"Late","On Time")) -> Late | J31: =IF(E31="Absent","Absent",IF(H31>=8,"Full Day",IF(H31>=4,"Half Day","Short"))) -> Full Day | K31: =IF(E31="Absent","N/A",IF(H31>=8,"Full Day",IF(H31>=4,"Half Day","Short"))) -> Full Day | L31: =IF(J31=K31,"✓ Match","⚠ Mismatch") -> ✓ Match | M31: =IF(AND(J31=K31,OR(E31="Present",E31="Work From Home",E31="Absent")),"CLEAN","REVIEW") -> CLEAN
A32: EMP028 | B32: Naveen Raj | C32: IT | D32: 2026-01-01 | E32: Present | F32: 08:00 | G32: 15:10 | H32: =IFERROR(MOD(TIMEVALUE(G32)-TIMEVALUE(F32),1)*24,0) -> 7.1666667 | I32: =IF(F32="No Login","",IF(TIMEVALUE(F32)>TIMEVALUE("09:00"),"Late","On Time")) -> On Time | J32: =IF(E32="Absent","Absent",IF(H32>=8,"Full Day",IF(H32>=4,"Half Day","Short"))) -> Half Day | K32: =IF(E32="Absent","N/A",IF(H32>=8,"Full Day",IF(H32>=4,"Half Day","Short"))) -> Half Day | L32: =IF(J32=K32,"✓ Match","⚠ Mismatch") -> ✓ Match | M32: =IF(AND(J32=K32,OR(E32="Present",E32="Work From Home",E32="Absent")),"CLEAN","REVIEW") -> CLEAN
A33: EMP003 | B33: Rahul Verma | C33: HR | D33: 2026-01-02 | E33: Present | F33: 08:05 | G33: 18:00 | H33: =IFERROR(MOD(TIMEVALUE(G33)-TIMEVALUE(F33),1)*24,0) -> 9.9166667 | I33: =IF(F33="No Login","",IF(TIMEVALUE(F33)>TIMEVALUE("09:00"),"Late","On Time")) -> On Time | J33: =IF(E33="Absent","Absent",IF(H33>=8,"Full Day",IF(H33>=4,"Half Day","Short"))) -> Full Day | K33: =IF(E33="Absent","N/A",IF(H33>=8,"Full Day",IF(H33>=4,"Half Day","Short"))) -> Full Day | L33: =IF(J33=K33,"✓ Match","⚠ Mismatch") -> ✓ Match | M33: =IF(AND(J33=K33,OR(E33="Present",E33="Work From Home",E33="Absent")),"CLEAN","REVIEW") -> CLEAN
A34: EMP006 | B34: Anjali | C34: IT | D34: 2026-01-02 | E34: Present | F34: 08:10 | G34: 16:30 | H34: =IFERROR(MOD(TIMEVALUE(G34)-TIMEVALUE(F34),1)*24,0) -> 8.3333333 | I34: =IF(F34="No Login","",IF(TIMEVALUE(F34)>TIMEVALUE("09:00"),"Late","On Time")) -> On Time | J34: =IF(E34="Absent","Absent",IF(H34>=8,"Full Day",IF(H34>=4,"Half Day","Short"))) -> Full Day | K34: =IF(E34="Absent","N/A",IF(H34>=8,"Full Day",IF(H34>=4,"Half Day","Short"))) -> Full Day | L34: =IF(J34=K34,"✓ Match","⚠ Mismatch") -> ✓ Match | M34: =IF(AND(J34=K34,OR(E34="Present",E34="Work From Home",E34="Absent")),"CLEAN","REVIEW") -> CLEAN
A35: EMP021 | B35: Nitin Sharma | C35: Sales | D35: 2026-01-02 | E35: Present | F35: 10:20 | G35: 20:20 | H35: =IFERROR(MOD(TIMEVALUE(G35)-TIMEVALUE(F35),1)*24,0) -> 10 | I35: =IF(F35="No Login","",IF(TIMEVALUE(F35)>TIMEVALUE("09:00"),"Late","On Time")) -> Late | J35: =IF(E35="Absent","Absent",IF(H35>=8,"Full Day",IF(H35>=4,"Half Day","Short"))) -> Full Day | K35: =IF(E35="Absent","N/A",IF(H35>=8,"Full Day",IF(H35>=4,"Half Day","Short"))) -> Full Day | L35: =IF(J35=K35,"✓ Match","⚠ Mismatch") -> ✓ Match | M35: =IF(AND(J35=K35,OR(E35="Present",E35="Work From Home",E35="Absent")),"CLEAN","REVIEW") -> CLEAN
A36: EMP020 | B36: Lakshmi Devi | C36: Sales | D36: 2026-01-02 | E36: Present | F36: 08:15 | G36: 16:30 | H36: =IFERROR(MOD(TIMEVALUE(G36)-TIMEVALUE(F36),1)*24,0) -> 8.25 | I36: =IF(F36="No Login","",IF(TIMEVALUE(F36)>TIMEVALUE("09:00"),"Late","On Time")) -> On Time | J36: =IF(E36="Absent","Absent",IF(H36>=8,"Full Day",IF(H36>=4,"Half Day","Short"))) -> Full Day | K36: =IF(E36="Absent","N/A",IF(H36>=8,"Full Day",IF(H36>=4,"Half Day","Short"))) -> Full Day | L36: =IF(J36=K36,"✓ Match","⚠ Mismatch") -> ✓ Match | M36: =IF(AND(J36=K36,OR(E36="Present",E36="Work From Home",E36="Absent")),"CLEAN","REVIEW") -> CLEAN
A37: EMP025 | B37: Varun Sethi | C37: HR | D37: 2026-01-02 | E37: Present | F37: 09:30 | G37: 16:00 | H37: =IFERROR(MOD(TIMEVALUE(G37)-TIMEVALUE(F37),1)*24,0) -> 6.5 | I37: =IF(F37="No Login","",IF(TIMEVALUE(F37)>TIMEVALUE("09:00"),"Late","On Time")) -> Late | J37: =IF(E37="Absent","Absent",IF(H37>=8,"Full Day",IF(H37>=4,"Half Day","Short"))) -> Half Day | K37: =IF(E37="Absent","N/A",IF(H37>=8,"Full Day",IF(H37>=4,"Half Day","Short"))) -> Half Day | L37: =IF(J37=K37,"✓ Match","⚠ Mismatch") -> ✓ Match | M37: =IF(AND(J37=K37,OR(E37="Present",E37="Work From Home",E37="Absent")),"CLEAN","REVIEW") -> CLEAN
A38: EMP029 | B38: Sanjana Roy | C38: IT | D38: 2026-01-02 | E38: Present | F38: 09:20 | G38: 16:00 | H38: =IFERROR(MOD(TIMEVALUE(G38)-TIMEVALUE(F38),1)*24,0) -> 6.6666667 | I38: =IF(F38="No Login","",IF(TIMEVALUE(F38)>TIMEVALUE("09:00"),"Late","On Time")) -> Late | J38: =IF(E38="Absent","Absent",IF(H38>=8,"Full Day",IF(H38>=4,"Half Day","Short"))) -> Half Day | K38: =IF(E38="Absent","N/A",IF(H38>=8,"Full Day",IF(H38>=4,"Half Day","Short"))) -> Half Day | L38: =IF(J38=K38,"✓ Match","⚠ Mismatch") -> ✓ Match | M38: =IF(AND(J38=K38,OR(E38="Present",E38="Work From Home",E38="Absent")),"CLEAN","REVIEW") -> CLEAN
A39: EMP028 | B39: Naveen Raj | C39: IT | D39: 2026-01-02 | E39: Present | F39: 08:00 | G39: 18:30 | H39: =IFERROR(MOD(TIMEVALUE(G39)-TIMEVALUE(F39),1)*24,0) -> 10.5 | I39: =IF(F39="No Login","",IF(TIMEVALUE(F39)>TIMEVALUE("09:00"),"Late","On Time")) -> On Time | J39: =IF(E39="Absent","Absent",IF(H39>=8,"Full Day",IF(H39>=4,"Half Day","Short"))) -> Full Day | K39: =IF(E39="Absent","N/A",IF(H39>=8,"Full Day",IF(H39>=4,"Half Day","Short"))) -> Full Day | L39: =IF(J39=K39,"✓ Match","⚠ Mismatch") -> ✓ Match | M39: =IF(AND(J39=K39,OR(E39="Present",E39="Work From Home",E39="Absent")),"CLEAN","REVIEW") -> CLEAN
A40: EMP013 | B40: Ramesh | C40: Sales | D40: 2026-01-02 | E40: Absent | F40: No Login | G40: No Logout | H40: 0 | I40: =IF(F40="No Login","",IF(TIMEVALUE(F40)>TIMEVALUE("09:00"),"Late","On Time")) | J40: =IF(E40="Absent","Absent",IF(H40>=8,"Full Day",IF(H40>=4,"Half Day","Short"))) -> Absent | K40: =IF(E40="Absent","N/A",IF(H40>=8,"Full Day",IF(H40>=4,"Half Day","Short"))) -> N/A | L40: =IF(J40=K40,"✓ Match","⚠ Mismatch") -> ⚠ Mismatch | M40: =IF(AND(J40=K40,OR(E40="Present",E40="Work From Home",E40="Absent")),"CLEAN","REVIEW") -> REVIEW
...

Sheet Dept Attendance
A3: Row Labels | B3: Attendance Count
A4: Sales | B4: 225
A5: IT | B5: 200
A6: HR | B6: 150
A7: Finance | B7: 125
A8: Operations | B8: 50
A9: Grand Total | B9: 750

Sheet Status Overview
A3: Row Labels | B3: Count of Employee Name
A4: Absent | B4: 152
A5: Present | B5: 525
A6: Work From Home | B6: 73
A7: Grand Total | B7: 750

Sheet Daily Trend
A1: Status | B1: (All)
A3: Row Labels | B3: Count of Emp ID
A4: 2026-01-01 | B4: 30
A5: 2026-01-02 | B5: 30
A6: 2026-01-05 | B6: 30
A7: 2026-01-06 | B7: 30
A8: 2026-01-07 | B8: 30
A9: 2026-01-08 | B9: 30
A10: 2026-01-09 | B10: 30
A11: 2026-01-12 | B11: 30
A12: 2026-01-13 | B12: 30
A13: 2026-01-14 | B13: 30
A14: 2026-01-15 | B14: 30
A15: 2026-01-16 | B15: 30
... A29: Grand Total | B29: 750

Sheet Data Quality
A3: Row Labels | B3: Count of Emp ID
A4: REVIEW | B4: 152
A5: CLEAN | B5: 598
A6: Grand Total | B6: 750

Sheet KPI Dashboard
A1: EMPLOYEE ATTENDANCE KPI DASHBOARD
A3: Total Records | B3: =COUNTA('Cleaned Data'!A3:A752) -> 750 | D3: Avg Hours / Working Day | E3: =AVERAGEIFS('Cleaned Data'!H3:H752,'Cleaned Data'!E3:E752,"<>Absent") -> 9.3658027
A4: Unique Employees | B4: {=COUNTA(_xlfn.UNIQUE(_xlfn._xlws.FILTER('Cleaned Data'!A3:A752,'Cleaned Data'!A3:A752<>"")))} -> 30
A5: Attendance Rate | B5: =(COUNTIF('Cleaned Data'!E3:E752,"Present")+COUNTIF('Cleaned Data'!E3:E752,"Work From Home"))/COUNTA('Cleaned Data'!A3:A752) -> 0.79733333
A6: Absence Rate | B6: =COUNTIF('Cleaned Data'!E3:E752,"Absent")/COUNTA('Cleaned Data'!A3:A752) -> 0.20266667

Sheet Dashboard
